[{"owner":{"profile_image":"https://i.stack.imgur.com/vNRRo.jpg?s=256&g=1","account_id":3514618,"user_type":"registered","user_id":2938364,"link":"https://stackoverflow.com/users/2938364/markus-weninger","reputation":12090,"display_name":"Markus Weninger","accept_rate":88},"content_license":"CC BY-SA 4.0","link":"https://stackoverflow.com/questions/72598626/official-recommendation-coding-style-guide-on-using-multiple-throws-tags-for","last_activity_date":1655113252,"creation_date":1655102168,"answer_count":2,"title":"Official recommendation / coding style guide on using multiple @throws tags for the same exception in JavaDoc","body":"<p>I just recently found out that <a href=\"https://stackoverflow.com/questions/9229991/can-i-use-multiple-throws-tags-for-the-same-exception-in-javadoc\">one can use multiple <code>@throws</code> tags for the same exception in Javadoc</a>.</p>\n<p>One of my students used it to document one of his methods in <a href=\"https://en.wikipedia.org/wiki/Connect_Four\" rel=\"noreferrer\">Connect Four</a>:</p>\n<pre><code>/*\n * ...\n * @throws IllegalArgumentException if the number of rows or columns is invalid \n * @throws IllegalArgumentException if one of the players has {@link Stone#None} as stone\n * @throws IllegalStateException if both players use the same stone color\n */\npublic void doSomething(...) { ... }\n</code></pre>\n<p>Now my (and his) question: Is there an official style guide or a general recommendation on whether to use a single <code>@throws</code> tag or &quot;is it fine&quot; to use multiple ones per exception type?</p>\n","question_id":72598626,"tags":["java","exception","javadoc","code-documentation","throws"],"score":7,"accepted_answer_id":72600530,"is_answered":true,"view_count":267},{"owner":{"profile_image":"https://www.gravatar.com/avatar/4d14bb9e5c27d2d26f8f6f011cc4571a?s=256&d=identicon&r=PG","account_id":1442354,"user_type":"registered","user_id":1362082,"link":"https://stackoverflow.com/users/1362082/franz","reputation":1913,"display_name":"Franz","accept_rate":53},"content_license":"CC BY-SA 4.0","link":"https://stackoverflow.com/questions/72595022/throw-own-defined-exception-in-visitor-pattern-java","last_activity_date":1655063114,"creation_date":1655060037,"answer_count":1,"title":"throw own defined exception in visitor pattern java","body":"<p>We  have to  write an app using the visitor design pattern  like ( <a href=\"https://www.baeldung.com/java-visitor-pattern\" rel=\"nofollow noreferrer\">https://www.baeldung.com/java-visitor-pattern</a> ) , one example  element looks like, implementing interface Stmt :</p>\n<pre><code>public class Call implements Stmt {\n    int hash_id;\n    private String id;\n    public Call(String id )   { this.id = id;}\n\n\n    public void accept(Visitor v) {\n        System.out.println(&quot;call.accept&quot;);\n        v.visit( this);\n    }\n\n    public String getId () {  return id;}\n    ....}\n</code></pre>\n<p>The vistor Interface  looks like this  code below , I may not change the  interface  code.</p>\n<pre><code>public interface Visitor {\n    ... \n    ...\n\n    void visit(Subroutine subroutine);\n\n    void visit(Call call);\n}\n</code></pre>\n<p>Inside the  Implementation  of an  Visitor (AbstractVisitor class) I have to throw a &quot;UndefinedSubroutineException if the id (type string)  of a call class is not yet  existing  in the hashtable SubBefehle.\nThe existing  code with try catch statemenets never send as an exception  to my testcase ....</p>\n<pre><code>public abstract class AbstractVisitor implements Visitor {\n.....\n private Hashtable&lt;String, Integer&gt; SubBefehle = new Hashtable&lt; String, Integer&gt;();\n\n@Override\npublic void visit(Call call)  {\n    ///  implementation work :\n\n       try {\n\n           IsFunctionNameExisting(call.getId());\n       }\n       catch (UndefinedSubroutineException e){\n          // throw new UndefinedSubroutineException(&quot;&quot;);\n       }\n}\n\npublic void IsFunctionNameExisting(String fctname) throws UndefinedSubroutineException {\n    boolean IsFound = false;\n\n    if (SubBefehle.containsKey(fctname)) {\n        System.out.println(&quot;Abstract visitor :  function name found -&gt; PASS  &quot;);\n        IsFound = true;\n    }\n    else {\n        System.out.println(&quot;Abstract visitor : function name not yet found -&gt; EXCEPTION &quot;);\n         throw new UndefinedSubroutineException(&quot; function name not found in function name list !&quot;);\n    }\n</code></pre>\n<p>if the call IsFunctionNameExisting(call.getId()) is false if the name is not found inside the hash table. My optional solution is also not working .</p>\n<pre><code>///  optional solution \n@Override\npublic void visit(Call call) throws UndefinedSubroutineException  {\n    ///  implementation work :\n           IsFunctionNameExisting(call.getId());\n       }\n</code></pre>\n<p>the corresponding testcase looks like this :</p>\n<pre><code>@Test \npublic void testUndefinedSubroutine() {\n    try {\n        PROG_TEST.accept(testVisitor);\n        fail(&quot;Exception expected&quot;);\n    } catch (UndefinedSubroutineException e) {\n       ........\n    }\n}\n</code></pre>\n<p>package turtle.logo;</p>\n<p>the defintion  of UndefinedSubroutineException goes like  this :</p>\n<pre><code>public class UndefinedSubroutineException  extends Throwable {\n\n    public  UndefinedSubroutineException (String message) {\n\n        super(message);\n    }\n}\n</code></pre>\n<p>PS:  I can't  change the test cases and the interface  definition  &amp;<br />\nI hope someone can help us with this problem.</p>\n","question_id":72595022,"tags":["java","exception","visitor-pattern"],"score":0,"is_answered":true,"view_count":92,"last_edit_date":1655063114},{"owner":{"profile_image":"https://www.gravatar.com/avatar/7c7ce5a047c15f100e5f8e224078d19a?s=256&d=identicon&r=PG&f=y&so-version=2","account_id":16720659,"user_type":"registered","user_id":12085680,"link":"https://stackoverflow.com/users/12085680/bugsoverflow","reputation":408,"display_name":"BugsOverflow"},"content_license":"CC BY-SA 4.0","link":"https://stackoverflow.com/questions/72582682/restcontrolleradvice-stops-working-properly-when-using-responsestatus-too","last_activity_date":1654950608,"creation_date":1654934788,"answer_count":1,"title":"@RestControllerAdvice Stops Working Properly when using @ResponseStatus too","body":"<p>I am using RestControllerAdvice to return custom responses dependending on the type of exception that happened (they are all runtime exceptions), this was the first time that I used it today and it was a very weird experience because at testing with postman and local it worked perfectly, but when we deployed to Quality it just did not work, everytime when there was an exception, the frontend did not even get any response, but in postman it kept working when making the exact request, so after like 5 hours of trying different things I tried removing the @ResponseStatus annotation and then it started responding properly to the frontend when exceptions happened, maybe I missed something about this annotation, here is the code of my RestControllerAdvice that does not work properly (when call from frontend):</p>\n<pre><code>@RestControllerAdvice\npublic class SftpExceptionHandler {\n\n    @ExceptionHandler(FileTypeNotFoundException.class)\n    @ResponseStatus(HttpStatus.NOT_FOUND)\n    public GeneralResponse handlerRequestException(FileTypeNotFoundException ex) {\n        return new GeneralResponse(HttpStatus.NOT_FOUND, ex.getMessage());\n    }\n\n    @ExceptionHandler(IncorrectConsecutiveException.class)\n    @ResponseStatus(HttpStatus.INTERNAL_SERVER_ERROR)\n    public GeneralResponse handlerRequestException(IncorrectConsecutiveException ex) {\n        return new GeneralResponse(HttpStatus.INTERNAL_SERVER_ERROR, ex.getMessage());\n    }\n\n    @ExceptionHandler(InvalidBinaryFileException.class)\n    @ResponseStatus(HttpStatus.BAD_REQUEST)\n    public GeneralResponse handlerRequestException(InvalidBinaryFileException ex) {\n        return new GeneralResponse(HttpStatus.BAD_REQUEST, ex.getMessage());\n    }\n\n}\n</code></pre>\n<p>Any idea why ResponseStatus annotation makes it fail? If I remove it then the frontend starts being able to read the response properly like the postman</p>\n<p>Example of one of my custom exceptions:</p>\n<pre><code>public class InvalidBinaryFileException extends RuntimeException {\n\n    private static final long serialVersionUID = 1L;\n\n    public InvalidBinaryFileException(String message) {\n        super(message);\n    }\n}\n</code></pre>\n","question_id":72582682,"tags":["java","spring-boot","rest","exception"],"score":0,"accepted_answer_id":72584310,"is_answered":true,"view_count":436},{"owner":{"profile_image":"https://www.gravatar.com/avatar/a771ce5c75531b9171379df1e7429c87?s=256&d=identicon&r=PG&f=y&so-version=2","account_id":17400576,"user_type":"registered","user_id":12609542,"link":"https://stackoverflow.com/users/12609542/david-blbulyan","reputation":35,"display_name":"David Blbulyan"},"closed_date":1654875510,"link":"https://stackoverflow.com/questions/72576694/how-can-i-force-to-work-option-binarry-class-files-in-idea-gui-designer-settin","last_activity_date":1654875371,"creation_date":1654874920,"answer_count":0,"title":"How can I force to work option &quot;binarry class files&quot; in IDEA GUI Designer settings?","body":"<p>I have a problem with running my GUI application, when I run my jar file. I get exception:</p>\n<pre><code>Exception in thread &quot;main&quot; java.awt.IllegalComponentStateException: contentPane cannot be set to null.\n    at java.desktop/javax.swing.JRootPane.setContentPane(JRootPane.java:594)\n    at java.desktop/javax.swing.JDialog.setContentPane(JDialog.java:1036)\n    at ui.ConnectToServerDialog.&lt;init&gt;(ConnectToServerDialog.java:22)\n    at common.Client.main(Client.java:14)\n</code></pre>\n<p>This is the rather common mistake. I read solutions, but everyone writes: &quot;choice java source code option&quot;, but it's uncomfortable for me, it fouls my code.\nI talk about this settings page in IDEA:\n<a href=\"https://i.stack.imgur.com/s6ERP.png\" rel=\"nofollow noreferrer\">gui designer settings screenshoot</a></p>\n<p>So, how can I fix the &quot;binary class files option&quot;?\nI create the dialog using Swing UI Designer in IDEA</p>\n","question_id":72576694,"tags":["java","user-interface","exception","intellij-idea"],"score":0,"closed_reason":"Duplicate","is_answered":false,"view_count":16,"last_edit_date":1654875371},{"owner":{"profile_image":"https://lh3.googleusercontent.com/a/AATXAJwVmYWkqfnXF0sDDhbWRtfXo8P2Eb5K_HIOPC-M=k-s256","account_id":25436265,"user_type":"registered","user_id":19239939,"link":"https://stackoverflow.com/users/19239939/batter","reputation":21,"display_name":"Batter"},"content_license":"CC BY-SA 4.0","link":"https://stackoverflow.com/questions/72559219/com-sun-tools-attach-agentloadexception-102-when-attaching","last_activity_date":1654773482,"creation_date":1654772787,"answer_count":0,"title":"com.sun.tools.attach.AgentLoadException: 102 when attaching","body":"<p>Stack Trace:</p>\n<pre><code>com.sun.tools.attach.AgentLoadException: 102\n    at jdk.attach/sun.tools.attach.HotSpotVirtualMachine.loadAgentLibrary(HotSpotVirtualMachine.java:109)\n    at jdk.attach/sun.tools.attach.HotSpotVirtualMachine.loadAgentLibrary(HotSpotVirtualMachine.java:120)\n    at jdk.attach/sun.tools.attach.HotSpotVirtualMachine.loadAgent(HotSpotVirtualMachine.java:148)\n    at Main.main(Main.java:31)\n</code></pre>\n<p>Code:</p>\n<pre><code>try {\n            attach.loadAgent(agent.getAbsolutePath() , &quot;1&quot;);\n            System.out.println(&quot;Agent was loaded.&quot;);\n        } catch (AgentLoadException e) {\n            System.err.println(&quot;Agent failed to load: &quot;);\n            e.printStackTrace();\n        } catch (AgentInitializationException e) {\n            System.err.println(&quot;Agent loaded, but failed to initialize: &quot;);\n            e.printStackTrace();\n        } catch (IOException e) {\n            e.printStackTrace();\n        }\n</code></pre>\n<p>Trying to attach an agent to a VM\nI get AgentLoadException:102\n102 upon looking up is ATTACH_ERROR_STARTFAIL\nAny ideas on how can I solve it?\nthanks.</p>\n","question_id":72559219,"tags":["java","exception","virtual-machine"],"score":2,"is_answered":false,"view_count":147,"last_edit_date":1654773482},{"owner":{"profile_image":"https://www.gravatar.com/avatar/02246f35e9f5c91a9d99a08b378e686c?s=256&d=identicon&r=PG&f=y&so-version=2","account_id":3931956,"user_type":"registered","user_id":3250086,"link":"https://stackoverflow.com/users/3250086/garyf","reputation":521,"display_name":"garyF"},"content_license":"CC BY-SA 3.0","link":"https://stackoverflow.com/questions/46091211/is-it-possible-to-resume-java-execution-after-exception","last_activity_date":1654755149,"creation_date":1504771805,"answer_count":3,"title":"Is it possible to resume Java execution after exception?","body":"<p>I have a ParentClass in a JAR, but not source code. I am implementing a SubClass, but i need to handle some corner cases.</p>\n\n<pre><code>class ParentClass {\n    void foo() {\n       … // lots of code 1\n       ; // can possibly throw NullPointerException \n       … // lots of code 2\n    }\n}\nclass SubClass extends ParentClass {\n    @Override\n    void foo() {\n       try {super.foo();}\n       catch(NullPointerException npe) {… /*handle exception*/}\n       finally {… /* resume lots of code 2 ? */}\n    }\n}\n</code></pre>\n\n<p>Is there a way to run the <code>//lots of code 2</code> part after handling the exception in the overriding method? I don't want to duplicate code, and cannot modify the ParentClass.</p>\n\n<p>P.S: The NullPointerException problem wasn't there in the ParentClass. But due to a different instantiation in SubClass, this problem may arise.</p>\n","question_id":46091211,"tags":["java","exception"],"score":5,"accepted_answer_id":46091271,"is_answered":true,"view_count":1159,"last_edit_date":1504772008},{"owner":{"profile_image":"https://lh3.googleusercontent.com/a/AATXAJzvamS-Qd3JPEKG7qqnzv1bmepOP3e5z8SZ-JSxAA=k-s256","account_id":25510797,"user_type":"registered","user_id":19302492,"link":"https://stackoverflow.com/users/19302492/santurron","reputation":1,"display_name":"santurron"},"content_license":"CC BY-SA 4.0","link":"https://stackoverflow.com/questions/72552971/what-is-the-best-way-to-prevent-the-program-from-breaking-when-receiving-a-user","last_activity_date":1654729229,"creation_date":1654728282,"answer_count":1,"title":"what is the best way to prevent the program from breaking when receiving a user input in java?","body":"<p>I learned exceptions with try catch, but i dont know if this is the propper way to secure the program. For example, when i use a scan.nextint, and the user enters a string, what is the best way to prevent that? Try catch, or something else?</p>\n","question_id":72552971,"tags":["java","validation","exception","input","java.util.scanner"],"score":-1,"is_answered":false,"view_count":32},{"owner":{"profile_image":"https://www.gravatar.com/avatar/28d7fc76db803c6757e7cfd2cde20354?s=256&d=identicon&r=PG","account_id":31293,"user_type":"registered","user_id":85821,"link":"https://stackoverflow.com/users/85821/bart-van-heukelom","reputation":43494,"display_name":"Bart van Heukelom","accept_rate":73},"content_license":"CC BY-SA 4.0","link":"https://stackoverflow.com/questions/72546743/outofmemoryerror-is-dangerous-but-why-more-dangerous-than-other-exceptions","last_activity_date":1654696757,"creation_date":1654695667,"answer_count":3,"title":"OutOfMemoryError is dangerous, but why more dangerous than other exceptions?","body":"<p>Conventional wisdom, on this site and elsewhere, is to not catch <code>java.lang.OutOfMemoryError</code>, except maybe for cleaning up, and just let the JVM crash and be restarted. The reason given for this is that it may have left the process in an invalid state. Okay, that seems like a good reason.</p>\n<p>But... that's not exclusive to <code>OutOfMemoryError</code>. Any exception may have left invalid state if it's not properly handled. Why is this considered okay:</p>\n<pre><code>String handleRequest(String name) {\n    try {\n        if (name.equals(&quot;buggy&quot;)) return buggy();\n        else if (name.equals(&quot;hungry&quot;)) return hungry();\n        else throw new IllegalArgumentException();\n    } catch (Exception e) { // &lt;-- not catching OutOfMemoryError\n        return &quot;Error: &quot; + e;\n    }\n}\n\nString buggy() {\n     bunnyLock.lock();\n     // oops! can throw ArrayIndexOutOfBoundsException due to using round instead of floor\n     var res = bunnies[(int) Math.round(Math.random() * bunnies.length)];\n     bunnyLock.unlock();\n    return res;\n}\n\nString hungry() {\n     var b = new byte[2_000_000_000]; // 2 GB because why not\n     ...\n}\n</code></pre>\n<p>But changing the catch to <code>Throwable</code> isn't? The <code>ArrayIndexOutOfBoundsException</code> is somehow considered more safe to catch, yet <code>buggy</code> is the method that leaves the state invalid, while a failed allocation in <code>hungry</code> is no problem.</p>\n<p>You might say, well, you should fix <code>buggy</code> to never leave state invalid:</p>\n<pre><code>String buggy() {\n     bunnyLock.lock();\n     try {\n         // oops! can throw ArrayIndexOutOfBoundsException due to using round instead of floor\n         return bunnies[(int) Math.round(Math.random() * bunnies.length)];\n     } finally {\n         bunnyLock.unlock();\n     }\n}\n</code></pre>\n<p>And I'd agree. In fact, I agree so much that I think every piece of code everywhere should be exception-safe like that. Then you may safely assume that even an <code>OutOfMemoryError</code> has not left any state invalid.</p>\n<p>So, am I missing something and is <code>OutOfMemoryError</code> really more dangerous?</p>\n","question_id":72546743,"tags":["java","exception","out-of-memory","indexoutofboundsexception"],"score":0,"accepted_answer_id":72547035,"is_answered":true,"view_count":157},{"owner":{"user_type":"does_not_exist","display_name":"user843337"},"content_license":"CC BY-SA 4.0","link":"https://stackoverflow.com/questions/8895091/how-can-i-set-the-message-on-an-exception-in-java","last_activity_date":1654621751,"creation_date":1326805549,"answer_count":8,"title":"How can I set the message on an exception in Java?","body":"<p>I want to set a custom exception message. However, I'm unsure of how to do this. Will I need to create a custom exception class or is there an easier way of doing this?</p>\n","question_id":8895091,"tags":["java","exception"],"score":26,"accepted_answer_id":8895131,"is_answered":true,"view_count":101042,"last_edit_date":1598921291},{"owner":{"profile_image":"https://www.gravatar.com/avatar/f7cf53bd8e67338b36d086f48477edfa?s=256&d=identicon&r=PG&f=y&so-version=2","account_id":22531657,"user_type":"registered","user_id":16723586,"link":"https://stackoverflow.com/users/16723586/kiznet007","reputation":15,"display_name":"Kiznet007"},"content_license":"CC BY-SA 4.0","link":"https://stackoverflow.com/questions/70008079/catching-exceptions-on-multiple-inputs-from-user-but-not-go-back-to-first-input","last_activity_date":1654610205,"creation_date":1637166287,"answer_count":4,"title":"Catching exceptions on multiple inputs from user but not go back to first input","body":"<p>Here is a small program that has multiple inputs from the user to get the smallest number entered. I'm trying to catch the InputMismatchException all in the same try/catch block but if the user inputs anything but an int on say the second or third int to be entered then it jumps back to the first input which the user already entered correctly. Is there a simpler way to fix this or do I need to create separate try/catch blocks for each input?</p>\n<pre><code>    public class GrabbingSmallestValueEntered {\n        \n        public static void main(String[] args) {\n            \n            //Scanner input = new Scanner(System.in);\n            boolean correctInput = true;\n            double a = 0;\n            double b = 0;\n            double c = 0;\n        \n            Scanner input = new Scanner(System.in);\n    \n                do {\n                    \n                    try {\n                    \n                    System.out.println(&quot;Input the first number: &quot;);\n                        a = input.nextDouble();\n                        \n                    System.out.println(&quot;Input the second number: &quot;);\n                        b = input.nextDouble();\n                        \n                    System.out.println(&quot;Input the third number: &quot;);\n                        c = input.nextDouble();\n                        correctInput = false;\n                    \n                }catch (InputMismatchException ie) {\n                    System.out.println(&quot;Only numbers allowed to be entered. No letters or words!&quot;);\n                    input.nextLine();\n                }\n    \n                \n            } while (correctInput);\n            \n                System.out.println(&quot;The smallest value is &quot; + smallest(a, b, c) + &quot;\\n&quot;);\n                \n}\n\npublic static double smallest(double a, double b, double c)\n{ \n\n  return Math.min(Math.min(a, b), c);\n}\n    \n    \n</code></pre>\n","question_id":70008079,"tags":["java","exception","input","try-catch"],"score":0,"is_answered":true,"view_count":904,"last_edit_date":1637198948},{"owner":{"profile_image":"https://lh3.googleusercontent.com/a/AATXAJwC88Hs0im1KqVpg1tDjWY0uWcimaxqZmOQbO-Y=k-s256","account_id":22839847,"user_type":"registered","user_id":16987056,"link":"https://stackoverflow.com/users/16987056/xx-x","reputation":1,"display_name":"xx x"},"content_license":"CC BY-SA 4.0","link":"https://stackoverflow.com/questions/69923637/indexoutofboundsexception-when-writing-a-list-of-players-to-a-file","last_activity_date":1636844095,"creation_date":1636608997,"answer_count":1,"title":"IndexOutOfBoundsException when writing a list of players to a file","body":"<p>I'm working on assignment for OOP and am stuck on the last step which is, &quot;Write all players to an output file that has a similar format of the input file.&quot;</p>\n<p>I need to know how to print all the info in the main to an output file with the same format as the input file and I use here ArrayList. it's working fine when I print the name and the height but when I want to print season or score, an exception appears.</p>\n<pre><code>pw.write(t1.getName() + &quot;; &quot; + t1.getCity() + &quot;\\n&quot;);\nfor (int m = 0; m &lt; p2.size(); m++) {\n    pw.print(t1.getPlayerList().get(m).getName() + &quot;; &quot; + t1.getPlayerList().get(m).getHeight() + &quot;; &quot;);\n    pw.println(t1.getPlayerList().get(m).getSeasonalRecords().get(m).getScores());\n} \n</code></pre>\n<p>it works well, but when I write</p>\n<pre><code>pw.println(t1.getPlayerList().get(m).getSeasonalRecords().get(m).getScores());\n</code></pre>\n<p>appear something is wrong\nthat the exceptions that I got</p>\n<blockquote>\n<p>Exception in thread &quot;main&quot; java.lang.IndexOutOfBoundsException: Index: 2, Size: 2\nat java.util.ArrayList.rangeCheck(ArrayList.java:657)\nat java.util.ArrayList.get(ArrayList.java:433)</p>\n</blockquote>\n","question_id":69923637,"tags":["java","exception","arraylist"],"score":-1,"is_answered":false,"view_count":92,"last_edit_date":1636609701},{"owner":{"profile_image":"https://lh4.googleusercontent.com/-XO5pmVBQa3Y/AAAAAAAAAAI/AAAAAAAAAAA/AMZuucnEnwT2r9D_vvE0tEkG_cwkXTZaXg/photo.jpg?sz=256","account_id":18554741,"user_type":"registered","user_id":13520144,"link":"https://stackoverflow.com/users/13520144/brunner-arthur","reputation":1,"display_name":"Brunner Arthur"},"content_license":"CC BY-SA 4.0","link":"https://stackoverflow.com/questions/69935845/java-lang-classnotfoundexception-net-sf-jasperreports-engine-jrexception","last_activity_date":1636741913,"creation_date":1636670564,"answer_count":1,"title":"java.lang.ClassNotFoundException: net.sf.jasperreports.engine.JRException","body":"<p>I am building a school management which needs to include terminal reports. I am using jasperreports but when I  run the codes in intellij, the reports are shown. But when I create the jar file and run the it, this is the error i encounter from the console .</p>\n<p>java.lang.ClassNotFoundException: net.sf.jasperreports.engine.JRException</p>\n","question_id":69935845,"tags":["java","exception","intellij-idea","compilation","report"],"score":0,"is_answered":false,"view_count":2762},{"owner":{"profile_image":"https://www.gravatar.com/avatar/446285f789b43eb050f92f100a7e7153?s=256&d=identicon&r=PG&f=y&so-version=2","account_id":11389024,"user_type":"registered","user_id":8349761,"link":"https://stackoverflow.com/users/8349761/thu-vix","reputation":43,"display_name":"thu.vix"},"closed_date":1661652725,"link":"https://stackoverflow.com/questions/69945215/unreported-exception-despite-of-try-catch-block","last_activity_date":1636730939,"creation_date":1636730598,"answer_count":1,"title":"unreported exception despite of try-catch block","body":"<p>I'm writing a program to practice throwing exceptions, and get compile error in one of the test:</p>\n<p>MyTest.java:29: error: unreported exception FileNotFoundException; must be caught or declared to be thrown:</p>\n<p>Assert.assertEquals(&quot;File Not Found&quot;, task2.fileNotFoundExTest());</p>\n<p>^</p>\n<pre><code>public void fileNotFoundEx() throws FileNotFoundException {\n        File fileName = new File(&quot;foo.txt&quot;);\n        BufferedReader rd = new BufferedReader(new FileReader(fileName));\n    }\n\npublic String fileNotFoundExTest() throws FileNotFoundException {\n        try {\n            fileNotFoundEx();\n        } catch (FileNotFoundException e) {\n            return &quot;File Not Found&quot;;\n        }\n        return &quot;No Error&quot;;\n    }\n</code></pre>\n<p>I don't know why this error occurs because I already put the method that causes exception in a try-catch block and add signature &quot;throws FileNotFoundException&quot; to both methods. Can anyone explain this?</p>\n","question_id":69945215,"tags":["java","exception"],"score":0,"accepted_answer_id":69945286,"closed_reason":"Duplicate","is_answered":true,"view_count":160},{"owner":{"profile_image":"https://i.stack.imgur.com/ojvZh.jpg?s=256&g=1","account_id":1316033,"user_type":"registered","user_id":1262865,"link":"https://stackoverflow.com/users/1262865/john16384","reputation":7855,"display_name":"john16384","accept_rate":50},"content_license":"CC BY-SA 4.0","link":"https://stackoverflow.com/questions/69944374/any-downsides-to-rethrowing-the-cause-of-a-checked-exception-as-an-unchecked-e","last_activity_date":1636727285,"creation_date":1636726825,"answer_count":0,"title":"Any downsides to rethrowing the *cause* of a checked exception as an unchecked exception?","body":"<p>I am writing a library in which I use checked exceptions internally as it helps to make sure that all paths handle certain exceptional cases. However, I don't want to burden the users of my library with these checked exceptions because of this rule I use:</p>\n<blockquote>\n<p>Exceptions should only be checked when they're out of control of both the caller and receiver.</p>\n</blockquote>\n<p>As most of the internal checked exceptions point to configuration problems or other issues that would never occur in a correct setup (and thus can be solved by the user), I wish to expose these as unchecked exceptions at my API boundaries.</p>\n<p>Normally, I would wrap these checked exceptions in an unchecked variant and be done with it. However, in this library, I sometimes have 3 levels of exception nesting already, for example:</p>\n<pre><code>hs.ddif.core.inject.instantiator.CheckedInstantiationException: Exception while constructing instance via Producer: hs.ddif.core.inject.instantiator.InstantiatorTest$H hs.ddif.core.inject.instantiator.InstantiatorTest$B.createH()\n(...)\nCaused by: java.lang.reflect.InvocationTargetException\n(...)\nCaused by: java.lang.RuntimeException: can't create H\n</code></pre>\n<p>Adding another level on top (which will not really add any relevant information) makes it harder to see the underlying cause and would require <code>instanceof</code> checks on <code>getCause</code> if user code does want to do specific handling. I currently do this:</p>\n<pre><code>catch(CheckedInstantiationException e) {\n    throw new InstantiationException(e);  // convert to runtime at API boundary\n}  \n</code></pre>\n<p>But what if I did this instead:</p>\n<pre><code>catch(CheckedInstantiationException e) {\n    throw new InstantiationException(e.getMessage(), e.getCause());  // convert to runtime at API boundary\n}  \n</code></pre>\n<p>This strips one nesting level but keeps the trace intact.  The trace looks slightly different, but still includes all lines involved.</p>\n<p>My question is, does this approach have any down sides that I'm missing?</p>\n","question_id":69944374,"tags":["java","exception","checked-exceptions","rethrow"],"score":2,"is_answered":false,"view_count":79,"last_edit_date":1636727285},{"owner":{"profile_image":"https://i.stack.imgur.com/shfxy.jpg?s=256&g=1","account_id":8604130,"user_type":"registered","user_id":6444776,"link":"https://stackoverflow.com/users/6444776/ommadawn","reputation":2552,"display_name":"Ommadawn","accept_rate":84},"content_license":"CC BY-SA 4.0","link":"https://stackoverflow.com/questions/69940918/hibernate-java-lang-illegalstateexception-transaction-already-active","last_activity_date":1636711601,"creation_date":1636710594,"answer_count":1,"title":"Hibernate java.lang.IllegalStateException: Transaction already active","body":"<p>I'm using Java EE + Hibernate 5 and recently I can see I've got some error messages in my Tomcat 9 logs saying:</p>\n<p><code>java.lang.IllegalStateException: Transaction already active</code></p>\n<p>The methods involved in the issue are:</p>\n<pre><code>// The caller method\nPic p = picDAO.getById(1000);\n\n\n// The Hibernate method\n@Override\npublic Pic getById(Integer id) throws BDException {\n    Session session = sessionFactory.getCurrentSession();\n    Transaction tx = session.getTransaction();\n    try {\n        tx.begin();\n        Pic p = (Pic) session.get(myClass, id);\n        tx.commit();\n        return p;\n    }\n    catch(........) {\n        // Exceptions here\n    }\n}\n</code></pre>\n<p>Edit. Here is the full stack trace (some messages are in spanish):</p>\n<pre><code>12-Nov-2021 09:30:43.875 GRAVE [http-nio-8080-exec-10] org.apache.catalina.core.StandardWrapperValve.invoke Servlet.service() para servlet [ViewPic] lanzó excepción\n        java.lang.IllegalStateException: Transaction already active\n                at org.hibernate.engine.transaction.internal.TransactionImpl.begin(TransactionImpl.java:74)\n                at project.dao.DAOGeneric.getById(DAOGeneric.java:268)\n                at project.controller.forwards.ViewPic.processRequest(ViewPic.java:86)\n                at project.controller.MainServlet.doGet(MainServlet.java:38)\n                at javax.servlet.http.HttpServlet.service(HttpServlet.java:655)\n                at javax.servlet.http.HttpServlet.service(HttpServlet.java:764)\n                at org.apache.catalina.core.ApplicationFilterChain.internalDoFilter(ApplicationFilterChain.java:227)\n                at org.apache.catalina.core.ApplicationFilterChain.doFilter(ApplicationFilterChain.java:162)\n                at org.apache.tomcat.websocket.server.WsFilter.doFilter(WsFilter.java:53)\n                at org.apache.catalina.core.ApplicationFilterChain.internalDoFilter(ApplicationFilterChain.java:189)\n                at org.apache.catalina.core.ApplicationFilterChain.doFilter(ApplicationFilterChain.java:162)\n                at project.controller.filters.TileConfigFilter.doFilter(TileConfigFilter.java:58)\n                at org.apache.catalina.core.ApplicationFilterChain.internalDoFilter(ApplicationFilterChain.java:189)\n                at org.apache.catalina.core.ApplicationFilterChain.doFilter(ApplicationFilterChain.java:162)\n                at org.apache.catalina.core.StandardWrapperValve.invoke(StandardWrapperValve.java:197)\n                at org.apache.catalina.core.StandardContextValve.invoke(StandardContextValve.java:97)\n                at org.apache.catalina.authenticator.AuthenticatorBase.invoke(AuthenticatorBase.java:540)\n                at org.apache.catalina.core.StandardHostValve.invoke(StandardHostValve.java:135)\n                at org.apache.catalina.valves.ErrorReportValve.invoke(ErrorReportValve.java:92)\n                at org.apache.catalina.core.StandardEngineValve.invoke(StandardEngineValve.java:78)\n                at org.apache.catalina.valves.RemoteIpValve.invoke(RemoteIpValve.java:769)\n                at org.apache.catalina.connector.CoyoteAdapter.service(CoyoteAdapter.java:357)\n                at org.apache.coyote.http11.Http11Processor.service(Http11Processor.java:382)\n                at org.apache.coyote.AbstractProcessorLight.process(AbstractProcessorLight.java:65)\n                at org.apache.coyote.AbstractProtocol$ConnectionHandler.process(AbstractProtocol.java:895)\n                at org.apache.tomcat.util.net.NioEndpoint$SocketProcessor.doRun(NioEndpoint.java:1722)\n                at org.apache.tomcat.util.net.SocketProcessorBase.run(SocketProcessorBase.java:49)\n                at org.apache.tomcat.util.threads.ThreadPoolExecutor.runWorker(ThreadPoolExecutor.java:1191)\n                at org.apache.tomcat.util.threads.ThreadPoolExecutor$Worker.run(ThreadPoolExecutor.java:659)\n                at org.apache.tomcat.util.threads.TaskThread$WrappingRunnable.run(TaskThread.java:61)\n                at java.base/java.lang.Thread.run(Thread.java:829)\n</code></pre>\n","question_id":69940918,"tags":["java","hibernate","session","tomcat","exception"],"score":0,"accepted_answer_id":69941125,"is_answered":true,"view_count":743,"last_edit_date":1636711193},{"owner":{"profile_image":"https://i.stack.imgur.com/TaCMM.jpg?s=256&g=1","account_id":1242916,"user_type":"registered","user_id":1205066,"link":"https://stackoverflow.com/users/1205066/sergey","reputation":437,"display_name":"Sergey","accept_rate":100},"content_license":"CC BY-SA 3.0","link":"https://stackoverflow.com/questions/23625440/design-pattern-for-cumulative-validation-violations","last_activity_date":1636636754,"creation_date":1399966950,"answer_count":5,"title":"Design pattern for cumulative validation violations","body":"<p>Let's imagine, that we have a process, which accepts data of the following type:</p>\n\n<pre><code>{\"date\":\"2014-05-05\", \"url\":\"http://some.website.com\",\"counter\":3}\n</code></pre>\n\n<ul>\n<li>This data should be validated <strong>formally</strong>: value of <code>date</code> should be a\nparseable date, <code>url</code> should also conform the normal url syntax.</li>\n<li>Also, this data should be validated <strong>logically</strong>: <code>date</code> should be in the future, <code>url</code> should be an accessible\naddress, returning <code>200 OK</code>.</li>\n</ul>\n\n<p>To make it clean, one must separate those two validation routines into different units (classes, utils, whatever). The desired final behaviour, however, must give user clear understanding of ALL violations, that are present in data. Something like: </p>\n\n<p><code>{\"Errors\":[\n     \"Specified date is not in the future\",//Formal validation failed\n     \"Specified URL has invalid syntax\"//Logical validation failed\n ]}</code></p>\n\n<ul>\n<li>I have seen some implementations of the required behaviour, but they\nuse those make use of <code>Error</code> objects and are full of checks like\n<code>Error.hasErrors()</code> or <code>error==null</code>, which does not look elegant.</li>\n<li>I have also seen the implementation of <code>javax.validation</code>, which gives you all violations  on all field at once. Same approach could be implemented for content validation, but I am not sure, that this is the best way to do this. </li>\n</ul>\n\n<p><strong>Question</strong>: what is the best practice for handling multiple exceptions/violations of various nature?</p>\n\n<p><strong>UPD:</strong> short digest of answers: collect <code>Violations</code>, build an <code>Exception</code>, containing their context, cause and description, use an interceptor to render. See reference links from answers:</p>\n\n<p><a href=\"http://beanvalidation.org/1.0/spec/\" rel=\"nofollow noreferrer\">http://beanvalidation.org/1.0/spec/</a> JSR 303 specification</p>\n\n<p><a href=\"http://docs.spring.io/spring/docs/3.2.x/spring-framework-reference/html/validation.html\" rel=\"nofollow noreferrer\">http://docs.spring.io/spring/docs/3.2.x/spring-framework-reference/html/validation.html</a> Spring Bean Validation</p>\n\n<p><a href=\"http://docs.oracle.com/javaee/6/tutorial/doc/gircz.html\" rel=\"nofollow noreferrer\">http://docs.oracle.com/javaee/6/tutorial/doc/gircz.html</a> Java EE validation</p>\n\n<p><a href=\"https://stackoverflow.com/questions/18314609/which-design-pattern-to-use-for-validation\">Which Design Pattern To Use For Validation</a></p>\n\n<p><a href=\"https://stackoverflow.com/questions/729379/why-not-use-exceptions-as-regular-flow-of-control\">Why not use exceptions as regular flow of control?</a></p>\n","question_id":23625440,"tags":["java","validation","design-patterns","exception"],"score":6,"accepted_answer_id":23625868,"is_answered":true,"view_count":4374,"last_edit_date":1495542721},{"owner":{"profile_image":"https://www.gravatar.com/avatar/e6d1d662f2b3873887e61dafbed6d2c1?s=256&d=identicon&r=PG","account_id":42657,"user_type":"registered","user_id":124339,"link":"https://stackoverflow.com/users/124339/johanna","reputation":27146,"display_name":"Johanna","accept_rate":46},"content_license":"CC BY-SA 3.0","link":"https://stackoverflow.com/questions/1070590/how-can-i-write-custom-exceptions","last_activity_date":1636527910,"creation_date":1246472266,"answer_count":5,"title":"How can I write custom Exceptions?","body":"<p>How can I create a new <code>Exception</code> different from the pre-made types?</p>\n\n<pre><code>public class InvalidBankFeeAmountException extends Exception{\n    public InvalidBankFeeAmountException(String message){\n        super(message);\n    }\n }\n</code></pre>\n\n<p>It will show the warning for the <strong>InvalidBankFeeAmountException</strong> which is written in the first line.</p>\n","question_id":1070590,"tags":["java","exception"],"score":54,"accepted_answer_id":1070593,"is_answered":true,"view_count":57110,"last_edit_date":1438251126},{"owner":{"profile_image":"https://www.gravatar.com/avatar/d172333ccceefbcc91c2f38bbd30b332?s=256&d=identicon&r=PG","account_id":2489985,"user_type":"registered","user_id":2167671,"link":"https://stackoverflow.com/users/2167671/isaac-smith","reputation":173,"display_name":"Isaac Smith"},"content_license":"CC BY-SA 3.0","link":"https://stackoverflow.com/questions/15398703/exception-in-thread-main-java-util-nosuchelementexception","last_activity_date":1636471521,"creation_date":1363218627,"answer_count":6,"title":"Exception in thread &quot;main&quot; java.util.NoSuchElementException","body":"<p>Whenever I run this, the <code>chooseCave()</code> function works fine with the <code>in.nextInt()</code>. When I choose the cave, the messages pop up at 2-second intervals, and then as soon as it gets past that part, it gives me the error:</p>\n\n<pre><code>Exception in thread \"main\" java.util.NoSuchElementException: No line found\n    at java.util.Scanner.nextLine(Unknown Source)\n    at Dragon.main(Dragon.java:81)\n</code></pre>\n\n<p>I have tried <code>hasNextLine()</code> and <code>hasNextInt()</code>, and when I use <code>while hasNextLine()</code> in the <code>main</code> method, I get a ton more errors. When I use <code>while hasNextInt()</code> in the <code>chooseCave()</code> method, it doesn't accept my input.</p>\n\n<p>When I use <code>if hasNextInt()</code> in the <code>chooseCave()</code> method, it doesn't accept my input for the <code>playAgain</code> string, and goes straight into another game, but then the <code>hasNextInt()</code> boolean returns <code>false</code> and it spams \"Which cave...\" infinitely.</p>\n\n<p>I've gone through the error reports and the Java-docs and Stack Overflow's with similar problems. Please help.</p>\n\n<pre><code>import java.util.Scanner;\npublic class Dragon {\n\npublic static void displayIntro() {\n    System.out.println(\"You are in a land full of dragons. In front of you, \");\n    System.out.println(\"You see two caves. In one cave, the dragon is friendly\");\n    System.out.println(\"and will share his treasure with you. The other dragon\");\n    System.out.println(\"is greedy and hungry, and will eat you on sight\");\n    System.out.println(' ');\n}\n\npublic static int chooseCave() {\n    Scanner in = new Scanner(System.in);\n    int cave = 0;\n    while (cave != 1 &amp;&amp; cave != 2) {\n        System.out.println(\"Which cave will you go into? (1 or 2)\");\n\n        cave = in.nextInt();\n\n    }\n    in.close();\n    return cave;\n} \n\npublic static void checkCave(int chosenCave) {\n    System.out.println(\"You approach the cave...\");\n    try\n       {\n       // Sleep at least n milliseconds.\n       // 1 millisecond = 1/1000 of a second.\n       Thread.sleep( 2000 );\n       }\n    catch ( InterruptedException e )\n       {\n       System.out.println( \"awakened prematurely\" );\n       }\n    System.out.println(\"It is dark and spooky...\");\n    try\n       {\n       // Sleep at least n milliseconds.\n       // 1 millisecond = 1/1000 of a second.\n       Thread.sleep( 2000 );\n       }\n    catch ( InterruptedException e )\n       {\n       System.out.println( \"awakened prematurely\" );\n       }\n    System.out.println(\"A large dragon jumps out in front of you! He opens his jaws and...\");\n    try\n       {\n       // Sleep at least n milliseconds.\n       // 1 millisecond = 1/1000 of a second.\n       Thread.sleep( 2000 );\n       }\n    catch ( InterruptedException e )\n       {\n       System.out.println( \"awakened prematurely\" );\n       }\n\n    double friendlyCave = Math.ceil(Math.random() * 2);\n\n    if (chosenCave == friendlyCave) {\n        System.out.println(\"Gives you his treasure!\");\n    }\n    else {\n        System.out.println(\"Gobbles you down in one bite!\");\n    }\n\n\n\n}\npublic static void main(String[] args) {\n    Scanner inner = new Scanner(System.in);\n    String playAgain = \"yes\";\n    boolean play = true;\n    while (play) {\n        displayIntro();\n        int caveNumber = chooseCave();\n        checkCave(caveNumber);\n        System.out.println(\"Do you want to play again? (yes or no)\");\n        playAgain = inner.nextLine();\n        if (playAgain == \"yes\") {\n            play = true;\n        }\n        else {\n            play = false;\n        }\n    }\n    inner.close();\n\n}\n\n}\n</code></pre>\n","question_id":15398703,"tags":["java","exception","java.util.scanner"],"score":16,"accepted_answer_id":15398862,"is_answered":true,"view_count":208761,"last_edit_date":1363221839},{"owner":{"profile_image":"https://www.gravatar.com/avatar/bcdff3f230bd68f245c024dbb7b509e4?s=256&d=identicon&r=PG","account_id":37161,"user_type":"registered","user_id":106189,"link":"https://stackoverflow.com/users/106189/jim-hurne","reputation":7215,"display_name":"Jim Hurne","accept_rate":89},"content_license":"CC BY-SA 3.0","link":"https://stackoverflow.com/questions/2792728/when-is-it-appropriate-to-use-error-codes","last_activity_date":1636464598,"creation_date":1273286066,"answer_count":11,"title":"When is it appropriate to use error codes?","body":"<p>In languages that support exception objects (Java, C#), when is it appropriate to use <a href=\"http://en.wikipedia.org/wiki/Error_code\" rel=\"noreferrer\">error codes</a>? Is the use of error codes ever appropriate in typical enterprise applications?</p>\n\n<p>Many well-known software systems employ error codes (and a corresponding error code reference). Some examples include operating systems (Windows), databases (Oracle, DB2), and middle-ware products (WebLogic, WebSphere). What benefits do error codes provide? What are the disadvantages to using error codes?</p>\n","question_id":2792728,"tags":["c#","java","exception","error-handling","error-code"],"score":27,"accepted_answer_id":2792895,"is_answered":true,"view_count":5558,"last_edit_date":1316088046},{"owner":{"profile_image":"https://www.gravatar.com/avatar/f7cf53bd8e67338b36d086f48477edfa?s=256&d=identicon&r=PG&f=y&so-version=2","account_id":22531657,"user_type":"registered","user_id":16723586,"link":"https://stackoverflow.com/users/16723586/kiznet007","reputation":15,"display_name":"Kiznet007"},"content_license":"CC BY-SA 4.0","link":"https://stackoverflow.com/questions/69892732/catching-an-exception-when-a-user-inputs-an-integer-while-using-a-scanner-object","last_activity_date":1636438949,"creation_date":1636430962,"answer_count":1,"title":"Catching an exception when a user inputs an integer while using a Scanner object","body":"<p>I'm trying to catch an exception when the user enters any integer in the Scanner. I understand that using a String item = scan.nextLine() will allow for any input to be made including integers. I created a custom exception to catch the number 1. But what happens if the user inputs 999 or any other integer. How can I catch those other integers as part of the exception?</p>\n<p>import java.util.Scanner;\nimport java.lang.Exception;</p>\n<p>public class ExampleOne {</p>\n<pre><code>public static void main(String[] args) throws TestCustomException {\n    \n    System.out.println(&quot;Please enter any word:&quot;);\n    \n    try {\n        \n        Scanner scan = new Scanner(System.in);\n        String item = scan.nextLine();\n        if (item.contains(&quot;1&quot;)) {\n            throw new TestCustomException();\n        } \n    }catch (TestCustomException e) {\n        System.out.println(&quot;A problem occured:  &quot; + e);\n    }\n    \n    System.out.println(&quot;Thank you for using my application.&quot;);\n    \n}\n</code></pre>\n<p>}</p>\n<p>public class TestCustomException extends Exception {</p>\n<pre><code>TestCustomException (){\n    super(&quot;You can't enter any number value here&quot;);\n}\n</code></pre>\n<p>}</p>\n","question_id":69892732,"tags":["java","string","exception","input","integer"],"score":0,"accepted_answer_id":69893623,"is_answered":true,"view_count":409},{"owner":{"profile_image":"https://www.gravatar.com/avatar/2b39a4a337cd772a45c78706b173313d?s=256&d=identicon&r=PG","account_id":174942,"user_type":"registered","user_id":404608,"link":"https://stackoverflow.com/users/404608/magggi","reputation":1145,"display_name":"Magggi","accept_rate":14},"content_license":"CC BY-SA 2.5","link":"https://stackoverflow.com/questions/3625672/java-exception-handling","last_activity_date":1620299882,"creation_date":1283418876,"answer_count":8,"title":"Java exception handling","body":"<p>How do I use exceptions and exception handling to make my program continue even if an exception occurs while processing certain files in a set of files?</p>\n\n<p>I want my program to work fine for correct files while for those files which cause an exception in program, it should ignore.</p>\n\n<p>Regards,</p>\n\n<p>magggi</p>\n","question_id":3625672,"tags":["java","exception"],"score":7,"accepted_answer_id":3625721,"is_answered":true,"view_count":12012,"last_edit_date":1283419729},{"owner":{"profile_image":"https://i.stack.imgur.com/yVhlW.jpg?s=256&g=1","account_id":10108030,"user_type":"registered","user_id":7469973,"link":"https://stackoverflow.com/users/7469973/numan-gillani","reputation":499,"display_name":"Numan Gillani"},"content_license":"CC BY-SA 4.0","link":"https://stackoverflow.com/questions/51606891/how-to-set-icon-to-the-alert-dialog-programatically-in-android","last_activity_date":1620290564,"creation_date":1533019176,"answer_count":4,"title":"How to set Icon to the Alert Dialog Programatically in Android","body":"<p>Em using these statements for creating an Alert Dialog and set icon to it,</p>\n<pre><code>       AlertDialog.Builder builder = new AlertDialog.Builder(this);\n\n       builder.setIcon(this.getDrawable(R.drawable.video_downloader));\n\n       builder.setTitle(&quot;Congratulations !!!&quot;);\n\n       builder.show();\n</code></pre>\n<p>But it is crashing at setIcon, when I checked in drawable folder, the video_downloader icon is there already.</p>\n<pre><code>AndroidRuntime: FATAL EXCEPTION: main\njava.lang.IllegalStateException: Could not execute method of the activity\n    at android.view.View$1.onClick(View.java:3607)\n    at android.view.View.performClick(View.java:4212)\n    at android.view.View$PerformClick.run(View.java:17476)\n    at android.os.Handler.handleCallback(Handler.java:800)\n    at android.os.Handler.dispatchMessage(Handler.java:100)\n    at android.os.Looper.loop(Looper.java:194)\n    at android.app.ActivityThread.main(ActivityThread.java:5371)\n    at java.lang.reflect.Method.invokeNative(Native Method)\n    at java.lang.reflect.Method.invoke(Method.java:525)\n    at com.android.internal.os.ZygoteInit$MethodAndArgsCaller.run(ZygoteInit.java:833)\n    at com.android.internal.os.ZygoteInit.main(ZygoteInit.java:600)\n    at dalvik.system.NativeStart.main(Native Method)\n Caused by: java.lang.reflect.InvocationTargetException\n    at java.lang.reflect.Method.invokeNative(Native Method)\n    at java.lang.reflect.Method.invoke(Method.java:525)\n    at android.view.View$1.onClick(View.java:3602)\n    at android.view.View.performClick(View.java:4212) \n    at android.view.View$PerformClick.run(View.java:17476) \n    at android.os.Handler.handleCallback(Handler.java:800) \n    at android.os.Handler.dispatchMessage(Handler.java:100) \n    at android.os.Looper.loop(Looper.java:194) \n    at android.app.ActivityThread.main(ActivityThread.java:5371) \n    at java.lang.reflect.Method.invokeNative(Native Method) \n    at java.lang.reflect.Method.invoke(Method.java:525) \n    at com.android.internal.os.ZygoteInit$MethodAndArgsCaller.run(ZygoteInit.java:833) \n    at com.android.internal.os.ZygoteInit.main(ZygoteInit.java:600) \n    at dalvik.system.NativeStart.main(Native Method) \n Caused by: **java.lang.NoSuchMethodError**: numan.downloader.Test.Front.getDrawable\n    at numan.downloader.Test.Front.GetMedia(Front.java:115)\n    at java.lang.reflect.Method.invokeNative(Native Method) \n    at java.lang.reflect.Method.invoke(Method.java:525) \n    at android.view.View$1.onClick(View.java:3602) \n    at android.view.View.performClick(View.java:4212) \n    at android.view.View$PerformClick.run(View.java:17476) \n    at android.os.Handler.handleCallback(Handler.java:800) \n    at android.os.Handler.dispatchMessage(Handler.java:100) \n    at android.os.Looper.loop(Looper.java:194) \n    at android.app.ActivityThread.main(ActivityThread.java:5371) \n    at java.lang.reflect.Method.invokeNative(Native Method) \n    at java.lang.reflect.Method.invoke(Method.java:525) \n    at com.android.internal.os.ZygoteInit$MethodAndArgsCaller.run(ZygoteInit.java:833) \n    at com.android.internal.os.ZygoteInit.main(ZygoteInit.java:600) \n    at dalvik.system.NativeStart.main(Native Method) \n</code></pre>\n<p>07-31 08:35:51.291 500-519/? E/AppErrorDialog: Failed to get ILowStorageHandle instance</p>\n","question_id":51606891,"tags":["java","android","exception","android-alertdialog","nosuchmethoderror"],"score":-1,"accepted_answer_id":51606936,"is_answered":true,"view_count":4635,"last_edit_date":1620290564},{"owner":{"profile_image":"https://graph.facebook.com/10159420994469363/picture?type=large","account_id":19934003,"user_type":"registered","user_id":14607078,"link":"https://stackoverflow.com/users/14607078/tom-ronaldo","reputation":21,"display_name":"Tom Ronaldo"},"content_license":"CC BY-SA 4.0","link":"https://stackoverflow.com/questions/67412378/handle-scanner-exception-on-java-program","last_activity_date":1620280407,"creation_date":1620279127,"answer_count":0,"title":"Handle Scanner exception on Java program","body":"<p>I am working on a school project. I have all the functionality working but when I submit the project through Mimir, during deposits and withdraws it gives the following error:</p>\n<pre><code>Enter the amount you want to Deposit :$Exception in thread &quot;main&quot; java.util.NoSuchElementException\n\n13 at java.util.Scanner.throwFor(Scanner.java:862)\n14 at java.util.Scanner.next(Scanner.java:1485)\n15 at java.util.Scanner.nextDouble(Scanner.java:2345)\n16 at BankAccount.deposit(BankAccount.java:24)\n17 at SavingsAccountDemo.main(SavingsAccountDemo.java:30)\n</code></pre>\n<p>The project does says the following: Please make sure that your classes throw appropriate exceptions when an attempt is made to insert invalid data.</p>\n<p>I tried to add the try and catch with <code>java.util.InputMismatchException e</code> but it doesn't seem to be fixing it. I think it's because the userInput is a double and they are entering something different. Any ideas how can I fix that? Here is the code:</p>\n<pre><code>///SavingsAccountDemo class\nimport java.util.*;\npublic class SavingsAccountDemo {\n    \n    public static void main(String[] args) {\n        \n        Scanner keyboard = new Scanner(System.in);\n        \n        double startingBalance;\n        double interestRate;\n        String userInput;\n                \n        System.out.print(&quot;Enter beginning balance :$&quot;);\n        startingBalance = keyboard.nextDouble();\n        \n        System.out.print(&quot;Enter interest rate(whole number) :%&quot;);\n        interestRate = keyboard.nextDouble();\n        \n        double bal = startingBalance;\n        double rate = interestRate;\n        \n        BankAccount ba = new BankAccount(startingBalance, interestRate);\n        BankDemo sv = new BankDemo(bal, rate);\n        \n        while(startingBalance &gt; -1) {\n            try {\n                System.out.println(&quot;Enter D for deposit&quot; + &quot;\\nEnter W to Withdraw&quot; + &quot;\\nEnter B for Balance&quot; + \n                                    &quot;\\nEnter M for Monthly Process&quot; + &quot;\\nEnter E to Exit&quot;);\n                userInput = keyboard.next().toLowerCase();\n                \n                if(&quot;d&quot;.equals(userInput)) {\n                    ba.deposit();\n                } else if(&quot;w&quot;.equals(userInput)) {\n                    ba.withdraw();\n                } else if(&quot;b&quot;.equals(userInput)) {\n                    ba.totalBalance();\n                } else if(&quot;m&quot;.equals(userInput)) {\n                    ba.monthlyProcess();\n                } else if(&quot;e&quot;.equals(userInput)) {\n                    ba.exit();\n                    break;\n                }\n                else {\n                    System.out.print(&quot;Error, option not valid\\n&quot;);\n                }\n            }\n            catch (java.util.InputMismatchException e) {\n                System.out.print(&quot;Error&quot;);\n            }\n        }\n    }\n\n}\n///BankAccount class\nimport java.util.*;\npublic class BankAccount {\n    protected double balance;\n    protected double numDeposits;\n    protected double numWithdrawals;\n    protected double annualRate;\n    protected double monthlyServCharg;\n    protected boolean active;\n    \n    Scanner keyboard = new Scanner(System.in);\n    \n    public BankAccount(double startingBalance, double interestRate) {\n        balance = startingBalance;\n        annualRate = interestRate /= 100.0;\n        if(balance &lt; 25) {\n            active = false;\n        } else\n            active = true;\n    }\n    public void deposit() {\n        try {\n        double valueD;\n        \n        System.out.print(&quot;Enter the amount you want to Deposit :$&quot;);\n        valueD = keyboard.nextDouble();\n        if(valueD &lt; 0) {\n            System.out.println(&quot;Error: Must enter positive value\\n&quot;);\n        }\n        if( balance + valueD &gt;= 25 &amp;&amp; !active) {\n            System.out.print(&quot;Your account is now ACTIVE\\n&quot;);\n            active = true;      \n        }\n        balance += valueD;\n        numDeposits++;\n        } \n        catch (java.util.InputMismatchException e){\n            keyboard.nextLine();\n        }\n    }\n    public void withdraw() {\n        try {\n            double valueW;\n            \n            System.out.print(&quot;Enter the amount you want to withdraw :$&quot;);\n            valueW = keyboard.nextDouble();\n            if(valueW &lt; 0) {\n                System.out.println(&quot;Error: Must enter positive value\\n&quot;);\n            }\n            balance -= valueW;\n            numWithdrawals++;\n            if(balance &lt; 0) {\n                System.out.print(&quot;ERROR: Transaction declined!! This transaction will cause overdraft or zero balance\\n&quot;);\n                balance += valueW;\n            } else if(balance &lt;= 25 &amp;&amp; active) {\n                System.out.print(&quot;Your balance is less than minimum balance. Your account is now INACTIVE\\n&quot;);\n                active = false;\n                }\n            if(numWithdrawals &gt; 4) {\n                balance --;\n                System.out.print(&quot;You have exceeded monthly limit of withdrawals. Fee of $1 charged\\n&quot;);\n            }\n        } \n        catch (java.util.InputMismatchException e) {\n            keyboard.nextLine();\n        }\n        \n    }\n    public void totalBalance() {\n        System.out.printf(&quot;Your Balance is: %.2f\\n&quot;, balance);\n    }\n    public void calcInterest() {\n        double monRate = annualRate / 12;\n        double monInt = balance * monRate;\n        balance += monInt;\n    }\n    public void monthlyProcess() {\n        calcInterest();\n        balance -= monthlyServCharg;\n        numWithdrawals = 0;\n        numDeposits = 0;\n        monthlyServCharg = 0;\n        System.out.printf(&quot;Your Balance after Monthly process is: %.2f\\n&quot;, balance);\n    }\n    \n    public void exit() {\n        totalBalance();\n        System.out.print(&quot;Thank you. Bye&quot;);\n    }\n}\n</code></pre>\n","question_id":67412378,"tags":["java","exception","java.util.scanner"],"score":0,"is_answered":false,"view_count":55,"last_edit_date":1620280407},{"owner":{"profile_image":"https://www.gravatar.com/avatar/00a87df6ac471bb0b3f6c52ae17f5ae2?s=256&d=identicon&r=PG&f=y&so-version=2","account_id":19184838,"user_type":"registered","user_id":14015832,"link":"https://stackoverflow.com/users/14015832/bayraktarmd","reputation":3,"display_name":"bayraktarmd"},"content_license":"CC BY-SA 4.0","link":"https://stackoverflow.com/questions/67408280/my-fixture-algorithm-throws-exception-when-there-are-odd-team-numbers","last_activity_date":1620249379,"creation_date":1620246162,"answer_count":1,"title":"My fixture algorithm throws exception when there are odd team numbers","body":"<p>My fixture generator algorithm throws java.lang.IndexOutOfBoundsException when the team list count is odd. I'm sending 21 sized team list and gives this exception. And throws the same exception even when it's 17, 19, 23. Here is the exception:</p>\n<pre><code>E/AndroidRuntime: FATAL EXCEPTION: main\nProcess: com.xelorium.soccerleaguetable, PID: 1189\njava.lang.IndexOutOfBoundsException: Index: 21, Size: 21\n    at java.util.LinkedList.checkElementIndex(LinkedList.java:555)\n    at java.util.LinkedList.get(LinkedList.java:476)\n    at com.xelorium.soccerleaguetable.FixtureGenerator.getFixtures(FixtureGenerator.java:34)\n</code></pre>\n<p>FixtureGenerator.java:</p>\n<pre><code>public class FixtureGenerator&lt;T extends Object&gt; {\n\npublic List&lt;List&lt;MatchModel&lt;T&gt;&gt;&gt; getFixtures(List&lt;T&gt; teams, boolean includeReverseFixtures) {\n\n    int numberOfTeams = teams.size();\n\n    boolean ghost = false;\n    if (numberOfTeams % 2 != 0) {\n        numberOfTeams++;\n        ghost = true;\n    }\n\n    int totalRounds = numberOfTeams - 1;\n    int matchesPerRound = numberOfTeams / 2;\n    List&lt;List&lt;MatchModel&lt;T&gt;&gt;&gt; rounds = new LinkedList&lt;List&lt;MatchModel&lt;T&gt;&gt;&gt;();\n\n    for (int round = 0; round &lt; totalRounds; round++) {\n        List&lt;MatchModel&lt;T&gt;&gt; fixtures = new LinkedList&lt;MatchModel&lt;T&gt;&gt;();\n        for (int match = 0; match &lt; matchesPerRound; match++) {\n            int home = (round + match) % (numberOfTeams - 1);\n            int away = (numberOfTeams - 1 - match + round) % (numberOfTeams - 1);\n\n            if (match == 0) {\n                away = numberOfTeams - 1;\n            }\n            //Here where it throws the exception\n            fixtures.add(new MatchModel&lt;T&gt;(teams.get(home), teams.get(away)));\n        }\n        rounds.add(fixtures);\n    }\n</code></pre>\n","question_id":67408280,"tags":["java","algorithm","exception","fixtures"],"score":-1,"accepted_answer_id":67408762,"is_answered":true,"view_count":80},{"owner":{"user_type":"does_not_exist","display_name":"user15613889"},"content_license":"CC BY-SA 4.0","link":"https://stackoverflow.com/questions/67402595/unsatisfieddependencyexception-with-rest-service","last_activity_date":1620242811,"creation_date":1620222424,"answer_count":0,"title":"UnsatisfiedDependencyException with REST service","body":"<p>I am trying to create some unit tests for my REST API service class. This service class implements a service interface. However, when I try to run my tests I get this error:</p>\n<blockquote>\n<p>org.springFramework.beans.factory.UnsatisfiedDependencyException: Error creating bean with name 'dev.x.y.unit.ContactServiceImplTest': Unsatisfied dependency expressed through field 'contactServiceImpl';</p>\n</blockquote>\n<p>My test class:</p>\n<pre><code>@ExtendWith(SpringExtension.class)\nclass ContactServiceImplTest {\n\n@MockBean\nprivate ContactRepository contactRepository;\n\n@Autowired\nprivate ContactServiceImpl contactServiceImpl;\n...\n</code></pre>\n<p>my contactServiceImpl implements from my ContactService, I have tried annotating with @Component and @Service, but I am still receiving the same error.</p>\n<p>ContactServiceImpl class:</p>\n<pre><code>@Service\n@Transactional\npublic class ContactServiceImpl implements ContactService {\n\nLogger logger = LoggerFactory.getLogger(ContactServiceImpl.class);\n\n@Autowired\nprivate final ContactRepository contactRepository;\n....\n</code></pre>\n<p>My interface:</p>\n<pre><code>@Service\npublic interface ContactService { ... }\n</code></pre>\n<p>Any advice would be amazing.</p>\n","question_id":67402595,"tags":["java","spring-boot","exception"],"score":0,"is_answered":false,"view_count":194,"last_edit_date":1620242811},{"owner":{"profile_image":"https://lh4.googleusercontent.com/-bJ9jv_1cz3s/AAAAAAAAAAI/AAAAAAAAAAA/ACHi3reGJuhQYXII5V4i830X3pOPBeNVhw/photo.jpg?sz=256","account_id":16816125,"user_type":"registered","user_id":12157888,"link":"https://stackoverflow.com/users/12157888/sheharyar-lodhi","reputation":1,"display_name":"Sheharyar Lodhi"},"content_license":"CC BY-SA 4.0","link":"https://stackoverflow.com/questions/67404990/dexguard-release-build-throws-error-java-lang-unsatisfiedlinkerror-dlopen-fail","last_activity_date":1620232040,"creation_date":1620231183,"answer_count":1,"title":"Dexguard release build throws error: java.lang.UnsatisfiedLinkError: dlopen failed: library &quot;libsuprema_libusb.so&quot; not found","body":"<p>I am trying to make dexguard release build having libraries .so files so when I attach the debugger</p>\n<p>adb logcat throws exception:</p>\n<p>java.lang.UnsatisfiedLinkError: dlopen failed: library &quot;libsuprema_libusb.so&quot; not found</p>\n<p>Please any one guide as i am using suprema slim2 biometric scanner and everything works great in simple release but when i make release protected build than face this issue</p>\n","question_id":67404990,"tags":["java","android","exception",".so","dexguard"],"score":0,"is_answered":false,"view_count":220},{"owner":{"profile_image":"https://i.stack.imgur.com/09bUc.jpg?s=256&g=1","account_id":6537227,"user_type":"registered","user_id":5056288,"link":"https://stackoverflow.com/users/5056288/phanik","reputation":21,"display_name":"Phanik"},"content_license":"CC BY-SA 4.0","link":"https://stackoverflow.com/questions/67400314/how-to-split-string-by-reading-text-from-file","last_activity_date":1620216209,"creation_date":1620213740,"answer_count":3,"title":"how to split string by reading text from file","body":"<p>I am trying to read os-release file on Linux and trying to get the OS version by finding VERSION_ID=&quot;12.3&quot; line. I wrote below piece of code but at the last after splitting the string first time I am unable to go further. I reached up to splitting to &quot;12.3&quot; from VERSION_ID, after this I applied split function again and getting &quot;java.lang.ArrayIndexOutOfBoundsException: Index 1 out of bounds for length 0&quot; error. , Need your help and valuable suggestions.</p>\n<pre><code>File fobj2 = new File(&quot;C:\\\\os-release&quot;);\nif(fobj2.exists() &amp;&amp; !fobj2.isDirectory())\n{\nScanner sc = new Scanner(fobj2);\nwhile(sc.hasNextLine())\n    {\n     String line = sc.nextLine();\n     //VERSION_ID=&quot;12.3&quot;\n     if(line.contains(&quot;VERSION_ID=&quot;))\n     {\n     System.out.println(&quot; VERSION_ID= &quot; + line );\n     String [] ver = line.split(&quot;=&quot;);\n     if(ver.length &gt; 1)\n     {\n         String [] ver_id = line.split(&quot;=&quot;);\n         System.out.println(&quot; ver_id.length &quot; + ver_id.length );\n         System.out.println(&quot; ver_id[0] &quot; + ver_id[0] );\n         System.out.println(&quot; ver_id[1] &quot; + ver_id[1] );\n         System.out.println(&quot; ver_id[1].length() &quot; + ver_id[1].length() );\n                     \n         String [] FinalVer1 = ver_id[1].split(&quot;.&quot;);\n\n         System.out.println(&quot; FinalVer1[1].length() &quot; + FinalVer1[1].length() );\n         System.out.println(&quot; FinalVer1[1] &quot; + FinalVer1[1] );\n     }\n     }                   \n}\n</code></pre>\n","question_id":67400314,"tags":["java","arrays","string","exception","split"],"score":0,"accepted_answer_id":67400921,"is_answered":true,"view_count":68},{"owner":{"profile_image":"https://www.gravatar.com/avatar/89d5fbaa2c35bf567d07b78af8ecd998?s=256&d=identicon&r=PG","account_id":2338912,"user_type":"registered","user_id":2050642,"link":"https://stackoverflow.com/users/2050642/user2050642","reputation":11,"display_name":"user2050642"},"content_license":"CC BY-SA 4.0","link":"https://stackoverflow.com/questions/14751256/how-to-pass-exceptions-globally-to-a-single-action-from-other-actions-in-struts","last_activity_date":1620184874,"creation_date":1360240483,"answer_count":1,"title":"How to pass exceptions globally to a single action from other actions in Struts 2","body":"<p>I want to pass exceptions globally to a single action file called <code>ErrorAction</code>, say from <code>Index</code> action.</p>\n<p><strong>Here's my <code>struts.xml</code> file:</strong></p>\n<pre class=\"lang-xml prettyprint-override\"><code>&lt;global-results&gt;    \n    &lt;result name=&quot;myErrorHandler&quot; type=&quot;redirectAction&quot;&gt;    \n        &lt;param name=&quot;actionName&quot;&gt;myError&lt;/param&gt;\n    &lt;/result&gt;    \n    &lt;result name=&quot;login&quot; type=&quot;tiles&quot;&gt;\n        login\n    &lt;/result&gt;    \n&lt;/global-results&gt;    \n\n&lt;global-exception-mappings&gt;    \n    &lt;exception-mapping exception=&quot;java.lang.Exception&quot; result=&quot;myErrorHandler&quot; /&gt;    \n&lt;/global-exception-mappings&gt;    \n\n&lt;action name=&quot;myError&quot; class=&quot;com.actions.ErrorAction&quot;&gt;    \n    &lt;interceptor-ref name=&quot;exception&quot; /&gt;    \n    &lt;interceptor-ref name=&quot;defaultStack&quot; /&gt;    \n    &lt;result name=&quot;error&quot; type=&quot;tiles&quot;&gt;error&lt;/result&gt;    \n&lt;/action&gt;   \n\n....    \n\n&lt;action name=&quot;Index&quot; class=&quot;com.actions.Index&quot;&gt;    \n    &lt;interceptor-ref name=&quot;defaultStack&quot; /&gt;    \n    &lt;result name=&quot;success&quot; type=&quot;tiles&quot;&gt;home&lt;/result&gt;    \n&lt;/action&gt;\n</code></pre>\n","question_id":14751256,"tags":["java","exception","struts2","xml-configuration","interceptorstack"],"score":1,"is_answered":false,"view_count":418,"last_edit_date":1617773655},{"owner":{"profile_image":"https://i.stack.imgur.com/MjbfY.jpg?s=256&g=1","account_id":5465673,"user_type":"registered","user_id":4346563,"link":"https://stackoverflow.com/users/4346563/iitrainii","reputation":11,"display_name":"iitrainii"},"content_license":"CC BY-SA 4.0","link":"https://stackoverflow.com/questions/67387023/how-to-unit-test-the-json-exception-and-hit-cover-the-catch-block","last_activity_date":1620139828,"creation_date":1620139501,"answer_count":1,"title":"How to unit test the JSON exception and hit/cover the catch block","body":"<p>Here is a snippet of the code I am trying to cover, specifically the catch block.</p>\n<pre><code>JSONObject bodyObject = new JSONObject();\nString body = null;\n\ntry{\n   body = bodyObject.put(DecisionTreeConstants.EDGE_ACCOUNT_STATUS, processStatusPretty).toString();\n} catch (JSONException e) {\n   LOGGER.debug(&quot; &quot;);\n}\n</code></pre>\n","question_id":67387023,"tags":["java","json","exception","junit","code-coverage"],"score":-1,"is_answered":false,"view_count":157},{"owner":{"profile_image":"https://www.gravatar.com/avatar/65cda677975b95a5e78c4ee663c08b19?s=256&d=identicon&r=PG&f=y&so-version=2","account_id":12019463,"user_type":"registered","user_id":8793412,"link":"https://stackoverflow.com/users/8793412/karthikeyan","reputation":1937,"display_name":"Karthikeyan","accept_rate":88},"content_license":"CC BY-SA 4.0","link":"https://stackoverflow.com/questions/67371571/code-terminated-once-exception-caught-java","last_activity_date":1620057484,"creation_date":1620055502,"answer_count":3,"title":"code terminated once exception caught java","body":"<p>I was expecting remaining code to continue even after throwing exception for some products. Please find my code below.</p>\n<pre><code>public class Example1 {\n\n    void productCheck(int[] weight) throws InvalidProductException {\n\n        for (int i = 0; i &lt; weight.length; i++) {\n            System.out.println(&quot;Product --&gt;&quot;+weight[i]);\n            if (weight[i] &lt; 100) {\n                System.out.println(&quot;Product exception--&gt;&quot;+weight[i]);\n                throw new InvalidProductException(&quot;Product Invalid&quot;);\n            }\n        }\n\n    }\n\n    public static void main(String args[]) {\n        Example1 obj = new Example1();\n        \n        int[] weight = {110, 60, 10, 20, 100, 60 };\n        try {\n            obj.productCheck(weight);\n            \n        } catch (InvalidProductException ex) {\n            System.out.println(&quot;Caught the exception for Product&quot;);\n            System.out.println(ex.getMessage());\n        } \n    }\n\n}\n\npublic class InvalidProductException extends Exception\n    {\npublic InvalidProductException(String s)\n    {\n    // Call constructor of parent Exception\n    super(s);\n    }\n}\n</code></pre>\n<p>Output :</p>\n<pre><code>Product --&gt;110\nProduct --&gt;60\nProduct exception--&gt;60\nCaught the exception for Product\nProduct Invalid\n</code></pre>\n","question_id":67371571,"tags":["java","exception"],"score":-1,"accepted_answer_id":67371946,"is_answered":true,"view_count":95}]